[2024-07-23T04:28:47.757+0000] {local_task_job_runner.py:120} INFO - ::group::Pre task execution logs
[2024-07-23T04:28:47.773+0000] {taskinstance.py:2076} INFO - Dependencies all met for dep_context=non-requeueable deps ti=<TaskInstance: elt_script_dag.run_elt_script manual__2024-07-23T04:27:12.076488+00:00 [queued]>
[2024-07-23T04:28:47.778+0000] {taskinstance.py:2076} INFO - Dependencies all met for dep_context=requeueable deps ti=<TaskInstance: elt_script_dag.run_elt_script manual__2024-07-23T04:27:12.076488+00:00 [queued]>
[2024-07-23T04:28:47.778+0000] {taskinstance.py:2306} INFO - Starting attempt 2 of 2
[2024-07-23T04:28:47.787+0000] {taskinstance.py:2330} INFO - Executing <Task(BashOperator): run_elt_script> on 2024-07-23 04:27:12.076488+00:00
[2024-07-23T04:28:47.793+0000] {warnings.py:112} WARNING - /home/***/.local/lib/python3.12/site-packages/***/task/task_runner/standard_task_runner.py:62: DeprecationWarning: This process (pid=56) is multi-threaded, use of fork() may lead to deadlocks in the child.
  pid = os.fork()

[2024-07-23T04:28:47.795+0000] {standard_task_runner.py:64} INFO - Started process 58 to run task
[2024-07-23T04:28:47.795+0000] {standard_task_runner.py:90} INFO - Running: ['***', 'tasks', 'run', 'elt_script_dag', 'run_elt_script', 'manual__2024-07-23T04:27:12.076488+00:00', '--job-id', '31', '--raw', '--subdir', 'DAGS_FOLDER/dag.py', '--cfg-path', '/tmp/tmpr9rqmc1k']
[2024-07-23T04:28:47.796+0000] {standard_task_runner.py:91} INFO - Job 31: Subtask run_elt_script
[2024-07-23T04:28:47.829+0000] {task_command.py:426} INFO - Running <TaskInstance: elt_script_dag.run_elt_script manual__2024-07-23T04:27:12.076488+00:00 [running]> on host f010ea18e9b8
[2024-07-23T04:28:47.892+0000] {taskinstance.py:2648} INFO - Exporting env vars: AIRFLOW_CTX_DAG_EMAIL='***@example.com' AIRFLOW_CTX_DAG_OWNER='***' AIRFLOW_CTX_DAG_ID='elt_script_dag' AIRFLOW_CTX_TASK_ID='run_elt_script' AIRFLOW_CTX_EXECUTION_DATE='2024-07-23T04:27:12.076488+00:00' AIRFLOW_CTX_TRY_NUMBER='2' AIRFLOW_CTX_DAG_RUN_ID='manual__2024-07-23T04:27:12.076488+00:00'
[2024-07-23T04:28:47.893+0000] {taskinstance.py:430} INFO - ::endgroup::
[2024-07-23T04:28:47.894+0000] {subprocess.py:63} INFO - Tmp dir root location: /tmp
[2024-07-23T04:28:47.894+0000] {subprocess.py:75} INFO - Running command: ['/usr/bin/bash', '-c', 'python /opt/***/scripts//elt_script.py']
[2024-07-23T04:28:47.905+0000] {subprocess.py:86} INFO - Output:
[2024-07-23T04:28:47.953+0000] {subprocess.py:93} INFO - /home/***/.local/bin/python: can't find '__main__' module in '/opt/***/scripts//elt_script.py'
[2024-07-23T04:28:47.956+0000] {subprocess.py:97} INFO - Command exited with return code 1
[2024-07-23T04:28:47.957+0000] {taskinstance.py:441} INFO - ::group::Post task execution logs
[2024-07-23T04:28:47.964+0000] {taskinstance.py:2905} ERROR - Task failed with exception
Traceback (most recent call last):
  File "/home/airflow/.local/lib/python3.12/site-packages/airflow/models/taskinstance.py", line 465, in _execute_task
    result = _execute_callable(context=context, **execute_callable_kwargs)
             ^^^^^^^^^^^^^^^^^^^^^^^^^^^^^^^^^^^^^^^^^^^^^^^^^^^^^^^^^^^^^
  File "/home/airflow/.local/lib/python3.12/site-packages/airflow/models/taskinstance.py", line 432, in _execute_callable
    return execute_callable(context=context, **execute_callable_kwargs)
           ^^^^^^^^^^^^^^^^^^^^^^^^^^^^^^^^^^^^^^^^^^^^^^^^^^^^^^^^^^^^
  File "/home/airflow/.local/lib/python3.12/site-packages/airflow/models/baseoperator.py", line 401, in wrapper
    return func(self, *args, **kwargs)
           ^^^^^^^^^^^^^^^^^^^^^^^^^^^
  File "/home/airflow/.local/lib/python3.12/site-packages/airflow/operators/bash.py", line 243, in execute
    raise AirflowException(
airflow.exceptions.AirflowException: Bash command failed. The command returned a non-zero exit code 1.
[2024-07-23T04:28:47.968+0000] {taskinstance.py:1206} INFO - Marking task as FAILED. dag_id=elt_script_dag, task_id=run_elt_script, run_id=manual__2024-07-23T04:27:12.076488+00:00, execution_date=20240723T042712, start_date=20240723T042847, end_date=20240723T042847
[2024-07-23T04:28:47.976+0000] {standard_task_runner.py:110} ERROR - Failed to execute job 31 for task run_elt_script (Bash command failed. The command returned a non-zero exit code 1.; 58)
[2024-07-23T04:28:48.009+0000] {local_task_job_runner.py:243} INFO - Task exited with return code 1
[2024-07-23T04:28:48.021+0000] {taskinstance.py:3503} INFO - 0 downstream tasks scheduled from follow-on schedule check
[2024-07-23T04:28:48.023+0000] {local_task_job_runner.py:222} INFO - ::endgroup::
