[2024-07-23T05:13:55.314+0000] {local_task_job_runner.py:120} INFO - ::group::Pre task execution logs
[2024-07-23T05:13:55.332+0000] {taskinstance.py:2076} INFO - Dependencies all met for dep_context=non-requeueable deps ti=<TaskInstance: elt_script_dag.run_elt_script manual__2024-07-23T05:13:52.473420+00:00 [queued]>
[2024-07-23T05:13:55.340+0000] {taskinstance.py:2076} INFO - Dependencies all met for dep_context=requeueable deps ti=<TaskInstance: elt_script_dag.run_elt_script manual__2024-07-23T05:13:52.473420+00:00 [queued]>
[2024-07-23T05:13:55.341+0000] {taskinstance.py:2306} INFO - Starting attempt 1 of 2
[2024-07-23T05:13:55.353+0000] {taskinstance.py:2330} INFO - Executing <Task(BashOperator): run_elt_script> on 2024-07-23 05:13:52.473420+00:00
[2024-07-23T05:13:55.360+0000] {warnings.py:112} WARNING - /home/***/.local/lib/python3.12/site-packages/***/task/task_runner/standard_task_runner.py:62: DeprecationWarning: This process (pid=63) is multi-threaded, use of fork() may lead to deadlocks in the child.
  pid = os.fork()

[2024-07-23T05:13:55.361+0000] {standard_task_runner.py:64} INFO - Started process 65 to run task
[2024-07-23T05:13:55.361+0000] {standard_task_runner.py:90} INFO - Running: ['***', 'tasks', 'run', 'elt_script_dag', 'run_elt_script', 'manual__2024-07-23T05:13:52.473420+00:00', '--job-id', '50', '--raw', '--subdir', 'DAGS_FOLDER/dag.py', '--cfg-path', '/tmp/tmpibe3dblm']
[2024-07-23T05:13:55.362+0000] {standard_task_runner.py:91} INFO - Job 50: Subtask run_elt_script
[2024-07-23T05:13:55.398+0000] {task_command.py:426} INFO - Running <TaskInstance: elt_script_dag.run_elt_script manual__2024-07-23T05:13:52.473420+00:00 [running]> on host ed5b129837b8
[2024-07-23T05:13:55.468+0000] {taskinstance.py:2648} INFO - Exporting env vars: AIRFLOW_CTX_DAG_EMAIL='***@example.com' AIRFLOW_CTX_DAG_OWNER='***' AIRFLOW_CTX_DAG_ID='elt_script_dag' AIRFLOW_CTX_TASK_ID='run_elt_script' AIRFLOW_CTX_EXECUTION_DATE='2024-07-23T05:13:52.473420+00:00' AIRFLOW_CTX_TRY_NUMBER='1' AIRFLOW_CTX_DAG_RUN_ID='manual__2024-07-23T05:13:52.473420+00:00'
[2024-07-23T05:13:55.469+0000] {taskinstance.py:430} INFO - ::endgroup::
[2024-07-23T05:13:55.470+0000] {subprocess.py:63} INFO - Tmp dir root location: /tmp
[2024-07-23T05:13:55.471+0000] {subprocess.py:75} INFO - Running command: ['/usr/bin/bash', '-c', 'python /opt/***/scripts/elt_script.py']
[2024-07-23T05:13:55.483+0000] {subprocess.py:86} INFO - Output:
[2024-07-23T05:14:01.739+0000] {subprocess.py:93} INFO - ELT script started...
[2024-07-23T05:14:01.740+0000] {subprocess.py:93} INFO - fetching videos...
[2024-07-23T05:14:01.740+0000] {subprocess.py:93} INFO - fetching videos...
[2024-07-23T05:14:01.740+0000] {subprocess.py:93} INFO - fetching videos...
[2024-07-23T05:14:01.741+0000] {subprocess.py:93} INFO - fetching videos...
[2024-07-23T05:14:01.741+0000] {subprocess.py:93} INFO - could not translate host name "postgres1" to address: Name or service not known
[2024-07-23T05:14:01.741+0000] {subprocess.py:93} INFO - 
[2024-07-23T05:14:01.742+0000] {subprocess.py:93} INFO - Traceback (most recent call last):
[2024-07-23T05:14:01.742+0000] {subprocess.py:93} INFO -   File "/opt/***/scripts/elt_script.py", line 54, in <module>
[2024-07-23T05:14:01.742+0000] {subprocess.py:93} INFO -     cursor.execute(insert_query, (formatted_time, rank, current_video['snippet']['title'], current_video['id'], current_video['snippet']['publishedAt'], current_video['snippet']['channelId'], current_video['snippet']['description'], current_video['snippet']['thumbnails'].get('maxres', current_video['snippet']['thumbnails'].get('default', {'url': ''}))['url'], current_video['contentDetails']['dimension'], current_video['statistics']['viewCount'], current_video['statistics']['likeCount'], current_video['statistics'].get('commentCount', -1), current_video['statistics']['favoriteCount'], current_video['snippet']['categoryId']))
[2024-07-23T05:14:01.743+0000] {subprocess.py:93} INFO -     ^^^^^^
[2024-07-23T05:14:01.743+0000] {subprocess.py:93} INFO - NameError: name 'cursor' is not defined
[2024-07-23T05:14:01.765+0000] {subprocess.py:97} INFO - Command exited with return code 1
[2024-07-23T05:14:01.766+0000] {taskinstance.py:441} INFO - ::group::Post task execution logs
[2024-07-23T05:14:01.774+0000] {taskinstance.py:2905} ERROR - Task failed with exception
Traceback (most recent call last):
  File "/home/airflow/.local/lib/python3.12/site-packages/airflow/models/taskinstance.py", line 465, in _execute_task
    result = _execute_callable(context=context, **execute_callable_kwargs)
             ^^^^^^^^^^^^^^^^^^^^^^^^^^^^^^^^^^^^^^^^^^^^^^^^^^^^^^^^^^^^^
  File "/home/airflow/.local/lib/python3.12/site-packages/airflow/models/taskinstance.py", line 432, in _execute_callable
    return execute_callable(context=context, **execute_callable_kwargs)
           ^^^^^^^^^^^^^^^^^^^^^^^^^^^^^^^^^^^^^^^^^^^^^^^^^^^^^^^^^^^^
  File "/home/airflow/.local/lib/python3.12/site-packages/airflow/models/baseoperator.py", line 401, in wrapper
    return func(self, *args, **kwargs)
           ^^^^^^^^^^^^^^^^^^^^^^^^^^^
  File "/home/airflow/.local/lib/python3.12/site-packages/airflow/operators/bash.py", line 243, in execute
    raise AirflowException(
airflow.exceptions.AirflowException: Bash command failed. The command returned a non-zero exit code 1.
[2024-07-23T05:14:01.778+0000] {taskinstance.py:1206} INFO - Marking task as UP_FOR_RETRY. dag_id=elt_script_dag, task_id=run_elt_script, run_id=manual__2024-07-23T05:13:52.473420+00:00, execution_date=20240723T051352, start_date=20240723T051355, end_date=20240723T051401
[2024-07-23T05:14:01.800+0000] {warnings.py:112} WARNING - /home/***/.local/lib/python3.12/site-packages/***/utils/email.py:154: RemovedInAirflow3Warning: Fetching SMTP credentials from configuration variables will be deprecated in a future release. Please set credentials using a connection instead.
  send_mime_email(e_from=mail_from, e_to=recipients, mime_msg=msg, conn_id=conn_id, dryrun=dryrun)

[2024-07-23T05:14:01.801+0000] {configuration.py:1053} WARNING - section/key [smtp/smtp_user] not found in config
[2024-07-23T05:14:01.801+0000] {email.py:271} INFO - Email alerting: attempt 1
[2024-07-23T05:14:01.807+0000] {configuration.py:1053} WARNING - section/key [smtp/smtp_user] not found in config
[2024-07-23T05:14:01.808+0000] {email.py:271} INFO - Email alerting: attempt 1
[2024-07-23T05:14:01.808+0000] {taskinstance.py:879} ERROR - Failed to send email to: ['***@example.com']
Traceback (most recent call last):
  File "/home/airflow/.local/lib/python3.12/site-packages/airflow/models/taskinstance.py", line 2479, in _run_raw_task
    self._execute_task_with_callbacks(context, test_mode, session=session)
  File "/home/airflow/.local/lib/python3.12/site-packages/airflow/models/taskinstance.py", line 2676, in _execute_task_with_callbacks
    result = self._execute_task(context, task_orig)
             ^^^^^^^^^^^^^^^^^^^^^^^^^^^^^^^^^^^^^^
  File "/home/airflow/.local/lib/python3.12/site-packages/airflow/models/taskinstance.py", line 2701, in _execute_task
    return _execute_task(self, context, task_orig)
           ^^^^^^^^^^^^^^^^^^^^^^^^^^^^^^^^^^^^^^^
  File "/home/airflow/.local/lib/python3.12/site-packages/airflow/models/taskinstance.py", line 465, in _execute_task
    result = _execute_callable(context=context, **execute_callable_kwargs)
             ^^^^^^^^^^^^^^^^^^^^^^^^^^^^^^^^^^^^^^^^^^^^^^^^^^^^^^^^^^^^^
  File "/home/airflow/.local/lib/python3.12/site-packages/airflow/models/taskinstance.py", line 432, in _execute_callable
    return execute_callable(context=context, **execute_callable_kwargs)
           ^^^^^^^^^^^^^^^^^^^^^^^^^^^^^^^^^^^^^^^^^^^^^^^^^^^^^^^^^^^^
  File "/home/airflow/.local/lib/python3.12/site-packages/airflow/models/baseoperator.py", line 401, in wrapper
    return func(self, *args, **kwargs)
           ^^^^^^^^^^^^^^^^^^^^^^^^^^^
  File "/home/airflow/.local/lib/python3.12/site-packages/airflow/operators/bash.py", line 243, in execute
    raise AirflowException(
airflow.exceptions.AirflowException: Bash command failed. The command returned a non-zero exit code 1.

During handling of the above exception, another exception occurred:

Traceback (most recent call last):
  File "/home/airflow/.local/lib/python3.12/site-packages/airflow/models/taskinstance.py", line 1063, in _email_alert
    send_email(task.email, subject, html_content)
  File "/home/airflow/.local/lib/python3.12/site-packages/airflow/utils/email.py", line 80, in send_email
    return backend(
           ^^^^^^^^
  File "/home/airflow/.local/lib/python3.12/site-packages/airflow/utils/email.py", line 154, in send_email_smtp
    send_mime_email(e_from=mail_from, e_to=recipients, mime_msg=msg, conn_id=conn_id, dryrun=dryrun)
  File "/home/airflow/.local/lib/python3.12/site-packages/airflow/utils/email.py", line 273, in send_mime_email
    smtp_conn = _get_smtp_connection(smtp_host, smtp_port, smtp_timeout, smtp_ssl)
                ^^^^^^^^^^^^^^^^^^^^^^^^^^^^^^^^^^^^^^^^^^^^^^^^^^^^^^^^^^^^^^^^^^
  File "/home/airflow/.local/lib/python3.12/site-packages/airflow/utils/email.py", line 317, in _get_smtp_connection
    return smtplib.SMTP(host=host, port=port, timeout=timeout)
           ^^^^^^^^^^^^^^^^^^^^^^^^^^^^^^^^^^^^^^^^^^^^^^^^^^^
  File "/usr/local/lib/python3.12/smtplib.py", line 255, in __init__
    (code, msg) = self.connect(host, port)
                  ^^^^^^^^^^^^^^^^^^^^^^^^
  File "/usr/local/lib/python3.12/smtplib.py", line 341, in connect
    self.sock = self._get_socket(host, port, self.timeout)
                ^^^^^^^^^^^^^^^^^^^^^^^^^^^^^^^^^^^^^^^^^^
  File "/usr/local/lib/python3.12/smtplib.py", line 312, in _get_socket
    return socket.create_connection((host, port), timeout,
           ^^^^^^^^^^^^^^^^^^^^^^^^^^^^^^^^^^^^^^^^^^^^^^^
  File "/usr/local/lib/python3.12/socket.py", line 853, in create_connection
    raise exceptions[0]
  File "/usr/local/lib/python3.12/socket.py", line 838, in create_connection
    sock.connect(sa)
ConnectionRefusedError: [Errno 111] Connection refused

During handling of the above exception, another exception occurred:

Traceback (most recent call last):
  File "/home/airflow/.local/lib/python3.12/site-packages/airflow/models/taskinstance.py", line 877, in _handle_failure
    task_instance.email_alert(error, failure_context["task"])
  File "/home/airflow/.local/lib/python3.12/site-packages/airflow/models/taskinstance.py", line 3163, in email_alert
    _email_alert(task_instance=self, exception=exception, task=task)
  File "/home/airflow/.local/lib/python3.12/site-packages/airflow/models/taskinstance.py", line 1065, in _email_alert
    send_email(task.email, subject, html_content_err)
  File "/home/airflow/.local/lib/python3.12/site-packages/airflow/utils/email.py", line 80, in send_email
    return backend(
           ^^^^^^^^
  File "/home/airflow/.local/lib/python3.12/site-packages/airflow/utils/email.py", line 154, in send_email_smtp
    send_mime_email(e_from=mail_from, e_to=recipients, mime_msg=msg, conn_id=conn_id, dryrun=dryrun)
  File "/home/airflow/.local/lib/python3.12/site-packages/airflow/utils/email.py", line 273, in send_mime_email
    smtp_conn = _get_smtp_connection(smtp_host, smtp_port, smtp_timeout, smtp_ssl)
                ^^^^^^^^^^^^^^^^^^^^^^^^^^^^^^^^^^^^^^^^^^^^^^^^^^^^^^^^^^^^^^^^^^
  File "/home/airflow/.local/lib/python3.12/site-packages/airflow/utils/email.py", line 317, in _get_smtp_connection
    return smtplib.SMTP(host=host, port=port, timeout=timeout)
           ^^^^^^^^^^^^^^^^^^^^^^^^^^^^^^^^^^^^^^^^^^^^^^^^^^^
  File "/usr/local/lib/python3.12/smtplib.py", line 255, in __init__
    (code, msg) = self.connect(host, port)
                  ^^^^^^^^^^^^^^^^^^^^^^^^
  File "/usr/local/lib/python3.12/smtplib.py", line 341, in connect
    self.sock = self._get_socket(host, port, self.timeout)
                ^^^^^^^^^^^^^^^^^^^^^^^^^^^^^^^^^^^^^^^^^^
  File "/usr/local/lib/python3.12/smtplib.py", line 312, in _get_socket
    return socket.create_connection((host, port), timeout,
           ^^^^^^^^^^^^^^^^^^^^^^^^^^^^^^^^^^^^^^^^^^^^^^^
  File "/usr/local/lib/python3.12/socket.py", line 853, in create_connection
    raise exceptions[0]
  File "/usr/local/lib/python3.12/socket.py", line 838, in create_connection
    sock.connect(sa)
ConnectionRefusedError: [Errno 111] Connection refused
[2024-07-23T05:14:01.821+0000] {standard_task_runner.py:110} ERROR - Failed to execute job 50 for task run_elt_script (Bash command failed. The command returned a non-zero exit code 1.; 65)
[2024-07-23T05:14:01.835+0000] {local_task_job_runner.py:243} INFO - Task exited with return code 1
[2024-07-23T05:14:01.848+0000] {taskinstance.py:3503} INFO - 0 downstream tasks scheduled from follow-on schedule check
[2024-07-23T05:14:01.850+0000] {local_task_job_runner.py:222} INFO - ::endgroup::
