[2024-07-23T04:16:35.871+0000] {local_task_job_runner.py:120} INFO - ::group::Pre task execution logs
[2024-07-23T04:16:35.891+0000] {taskinstance.py:2076} INFO - Dependencies all met for dep_context=non-requeueable deps ti=<TaskInstance: elt_script_dag.run_elt_script manual__2024-07-23T04:15:32.477126+00:00 [queued]>
[2024-07-23T04:16:35.897+0000] {taskinstance.py:2076} INFO - Dependencies all met for dep_context=requeueable deps ti=<TaskInstance: elt_script_dag.run_elt_script manual__2024-07-23T04:15:32.477126+00:00 [queued]>
[2024-07-23T04:16:35.898+0000] {taskinstance.py:2306} INFO - Starting attempt 2 of 2
[2024-07-23T04:16:35.908+0000] {taskinstance.py:2330} INFO - Executing <Task(BashOperator): run_elt_script> on 2024-07-23 04:15:32.477126+00:00
[2024-07-23T04:16:35.914+0000] {warnings.py:112} WARNING - /home/***/.local/lib/python3.12/site-packages/***/task/task_runner/standard_task_runner.py:62: DeprecationWarning: This process (pid=144) is multi-threaded, use of fork() may lead to deadlocks in the child.
  pid = os.fork()

[2024-07-23T04:16:35.915+0000] {standard_task_runner.py:64} INFO - Started process 146 to run task
[2024-07-23T04:16:35.916+0000] {standard_task_runner.py:90} INFO - Running: ['***', 'tasks', 'run', 'elt_script_dag', 'run_elt_script', 'manual__2024-07-23T04:15:32.477126+00:00', '--job-id', '22', '--raw', '--subdir', 'DAGS_FOLDER/dag.py', '--cfg-path', '/tmp/tmpcbix0k5h']
[2024-07-23T04:16:35.917+0000] {standard_task_runner.py:91} INFO - Job 22: Subtask run_elt_script
[2024-07-23T04:16:35.952+0000] {task_command.py:426} INFO - Running <TaskInstance: elt_script_dag.run_elt_script manual__2024-07-23T04:15:32.477126+00:00 [running]> on host f010ea18e9b8
[2024-07-23T04:16:36.008+0000] {taskinstance.py:2648} INFO - Exporting env vars: AIRFLOW_CTX_DAG_EMAIL='***@example.com' AIRFLOW_CTX_DAG_OWNER='***' AIRFLOW_CTX_DAG_ID='elt_script_dag' AIRFLOW_CTX_TASK_ID='run_elt_script' AIRFLOW_CTX_EXECUTION_DATE='2024-07-23T04:15:32.477126+00:00' AIRFLOW_CTX_TRY_NUMBER='2' AIRFLOW_CTX_DAG_RUN_ID='manual__2024-07-23T04:15:32.477126+00:00'
[2024-07-23T04:16:36.010+0000] {taskinstance.py:430} INFO - ::endgroup::
[2024-07-23T04:16:36.011+0000] {subprocess.py:63} INFO - Tmp dir root location: /tmp
[2024-07-23T04:16:36.011+0000] {subprocess.py:75} INFO - Running command: ['/usr/bin/bash', '-c', 'python /elt_script.py']
[2024-07-23T04:16:36.022+0000] {subprocess.py:86} INFO - Output:
[2024-07-23T04:16:36.064+0000] {subprocess.py:93} INFO - python: can't open file '/elt_script.py': [Errno 2] No such file or directory
[2024-07-23T04:16:36.068+0000] {subprocess.py:97} INFO - Command exited with return code 2
[2024-07-23T04:16:36.068+0000] {taskinstance.py:441} INFO - ::group::Post task execution logs
[2024-07-23T04:16:36.076+0000] {taskinstance.py:2905} ERROR - Task failed with exception
Traceback (most recent call last):
  File "/home/airflow/.local/lib/python3.12/site-packages/airflow/models/taskinstance.py", line 465, in _execute_task
    result = _execute_callable(context=context, **execute_callable_kwargs)
             ^^^^^^^^^^^^^^^^^^^^^^^^^^^^^^^^^^^^^^^^^^^^^^^^^^^^^^^^^^^^^
  File "/home/airflow/.local/lib/python3.12/site-packages/airflow/models/taskinstance.py", line 432, in _execute_callable
    return execute_callable(context=context, **execute_callable_kwargs)
           ^^^^^^^^^^^^^^^^^^^^^^^^^^^^^^^^^^^^^^^^^^^^^^^^^^^^^^^^^^^^
  File "/home/airflow/.local/lib/python3.12/site-packages/airflow/models/baseoperator.py", line 401, in wrapper
    return func(self, *args, **kwargs)
           ^^^^^^^^^^^^^^^^^^^^^^^^^^^
  File "/home/airflow/.local/lib/python3.12/site-packages/airflow/operators/bash.py", line 243, in execute
    raise AirflowException(
airflow.exceptions.AirflowException: Bash command failed. The command returned a non-zero exit code 2.
[2024-07-23T04:16:36.080+0000] {taskinstance.py:1206} INFO - Marking task as FAILED. dag_id=elt_script_dag, task_id=run_elt_script, run_id=manual__2024-07-23T04:15:32.477126+00:00, execution_date=20240723T041532, start_date=20240723T041635, end_date=20240723T041636
[2024-07-23T04:16:36.090+0000] {standard_task_runner.py:110} ERROR - Failed to execute job 22 for task run_elt_script (Bash command failed. The command returned a non-zero exit code 2.; 146)
[2024-07-23T04:16:36.130+0000] {local_task_job_runner.py:243} INFO - Task exited with return code 1
[2024-07-23T04:16:36.143+0000] {taskinstance.py:3503} INFO - 0 downstream tasks scheduled from follow-on schedule check
[2024-07-23T04:16:36.145+0000] {local_task_job_runner.py:222} INFO - ::endgroup::
