[2024-07-26T00:02:22.786+0000] {local_task_job_runner.py:120} INFO - ::group::Pre task execution logs
[2024-07-26T00:02:22.803+0000] {taskinstance.py:2076} INFO - Dependencies all met for dep_context=non-requeueable deps ti=<TaskInstance: elt_script_dag.run_dbt scheduled__2024-07-25T00:00:00+00:00 [queued]>
[2024-07-26T00:02:22.808+0000] {taskinstance.py:2076} INFO - Dependencies all met for dep_context=requeueable deps ti=<TaskInstance: elt_script_dag.run_dbt scheduled__2024-07-25T00:00:00+00:00 [queued]>
[2024-07-26T00:02:22.808+0000] {taskinstance.py:2306} INFO - Starting attempt 2 of 2
[2024-07-26T00:02:22.816+0000] {taskinstance.py:2330} INFO - Executing <Task(DockerOperator): run_dbt> on 2024-07-25 00:00:00+00:00
[2024-07-26T00:02:22.822+0000] {warnings.py:112} WARNING - /home/***/.local/lib/python3.12/site-packages/***/task/task_runner/standard_task_runner.py:62: DeprecationWarning: This process (pid=1502) is multi-threaded, use of fork() may lead to deadlocks in the child.
  pid = os.fork()

[2024-07-26T00:02:22.823+0000] {standard_task_runner.py:64} INFO - Started process 1504 to run task
[2024-07-26T00:02:22.823+0000] {standard_task_runner.py:90} INFO - Running: ['***', 'tasks', 'run', 'elt_script_dag', 'run_dbt', 'scheduled__2024-07-25T00:00:00+00:00', '--job-id', '121', '--raw', '--subdir', 'DAGS_FOLDER/dag.py', '--cfg-path', '/tmp/tmp21tcfoe_']
[2024-07-26T00:02:22.825+0000] {standard_task_runner.py:91} INFO - Job 121: Subtask run_dbt
[2024-07-26T00:02:22.858+0000] {task_command.py:426} INFO - Running <TaskInstance: elt_script_dag.run_dbt scheduled__2024-07-25T00:00:00+00:00 [running]> on host 6a3ef3606308
[2024-07-26T00:02:22.921+0000] {taskinstance.py:2648} INFO - Exporting env vars: AIRFLOW_CTX_DAG_EMAIL='***@example.com' AIRFLOW_CTX_DAG_OWNER='***' AIRFLOW_CTX_DAG_ID='elt_script_dag' AIRFLOW_CTX_TASK_ID='run_dbt' AIRFLOW_CTX_EXECUTION_DATE='2024-07-25T00:00:00+00:00' AIRFLOW_CTX_TRY_NUMBER='2' AIRFLOW_CTX_DAG_RUN_ID='scheduled__2024-07-25T00:00:00+00:00'
[2024-07-26T00:02:22.923+0000] {taskinstance.py:430} INFO - ::endgroup::
[2024-07-26T00:02:22.947+0000] {docker.py:367} INFO - Starting docker container from image ghcr.io/dbt-labs/dbt-postgres:1.8.2
[2024-07-26T00:02:22.955+0000] {docker.py:375} WARNING - Using remote engine or docker-in-docker and mounting temporary volume from host is not supported. Falling back to `mount_tmp_dir=False` mode. You can set `mount_tmp_dir` parameter to False to disable mounting and remove the warning
[2024-07-26T00:02:24.195+0000] {docker.py:438} INFO - [0m00:02:24  Running with dbt=1.8.3
[2024-07-26T00:02:24.343+0000] {docker.py:438} INFO - [0m00:02:24  Registered adapter: postgres=1.8.2
[2024-07-26T00:02:24.632+0000] {docker.py:438} INFO - [0m00:02:24  Found 7 models, 27 data tests, 415 macros
[2024-07-26T00:02:24.635+0000] {docker.py:438} INFO - [0m00:02:24
[2024-07-26T00:02:24.752+0000] {docker.py:438} INFO - [0m00:02:24  Concurrency: 1 threads (target='dev')
[2024-07-26T00:02:24.753+0000] {docker.py:438} INFO - [0m00:02:24
[2024-07-26T00:02:24.761+0000] {docker.py:438} INFO - [0m00:02:24  1 of 7 START sql view model public.channel_rankings ............................ [RUN]
[2024-07-26T00:02:24.872+0000] {docker.py:438} INFO - [0m00:02:24  1 of 7 OK created sql view model public.channel_rankings ....................... [[32mCREATE VIEW[0m in 0.11s]
[2024-07-26T00:02:24.875+0000] {docker.py:438} INFO - [0m00:02:24  2 of 7 START sql view model public.source_stop_words ........................... [RUN]
[2024-07-26T00:02:24.940+0000] {docker.py:438} INFO - [0m00:02:24  2 of 7 OK created sql view model public.source_stop_words ...................... [[32mCREATE VIEW[0m in 0.06s]
[2024-07-26T00:02:24.943+0000] {docker.py:438} INFO - [0m00:02:24  3 of 7 START sql view model public.source_videos ............................... [RUN]
[2024-07-26T00:02:25.013+0000] {docker.py:438} INFO - [0m00:02:25  3 of 7 OK created sql view model public.source_videos .......................... [[32mCREATE VIEW[0m in 0.07s]
[2024-07-26T00:02:25.016+0000] {docker.py:438} INFO - [0m00:02:25  4 of 7 START sql view model public.trending_video_counts_per_channel ........... [RUN]
[2024-07-26T00:02:25.064+0000] {docker.py:438} INFO - [0m00:02:25  4 of 7 ERROR creating sql view model public.trending_video_counts_per_channel .. [[31mERROR[0m in 0.05s]
[2024-07-26T00:02:25.068+0000] {docker.py:438} INFO - [0m00:02:25  5 of 7 START sql view model public.view_ranks .................................. [RUN]
[2024-07-26T00:02:25.115+0000] {docker.py:438} INFO - [0m00:02:25  5 of 7 ERROR creating sql view model public.view_ranks ......................... [[31mERROR[0m in 0.05s]
[2024-07-26T00:02:25.118+0000] {docker.py:438} INFO - [0m00:02:25  6 of 7 START sql view model public.word_counts_title ........................... [RUN]
[2024-07-26T00:02:25.177+0000] {docker.py:438} INFO - [0m00:02:25  6 of 7 OK created sql view model public.word_counts_title ...................... [[32mCREATE VIEW[0m in 0.06s]
[2024-07-26T00:02:25.180+0000] {docker.py:438} INFO - [0m00:02:25  7 of 7 START sql view model public.word_counts_title_distinct .................. [RUN]
[2024-07-26T00:02:25.220+0000] {docker.py:438} INFO - [0m00:02:25  7 of 7 ERROR creating sql view model public.word_counts_title_distinct ......... [[31mERROR[0m in 0.04s]
[2024-07-26T00:02:25.240+0000] {docker.py:438} INFO - [0m00:02:25
[2024-07-26T00:02:25.241+0000] {docker.py:438} INFO - [0m00:02:25  Finished running 7 view models in 0 hours 0 minutes and 0.60 seconds (0.60s).
[2024-07-26T00:02:25.337+0000] {docker.py:438} INFO - [0m00:02:25
[2024-07-26T00:02:25.338+0000] {docker.py:438} INFO - [0m00:02:25  [31mCompleted with 3 errors and 0 warnings:[0m
[2024-07-26T00:02:25.338+0000] {docker.py:438} INFO - [0m00:02:25
[2024-07-26T00:02:25.339+0000] {docker.py:438} INFO - [0m00:02:25    Database Error in model trending_video_counts_per_channel (models/mart/trending_video_counts_per_channel.sql)
[2024-07-26T00:02:25.339+0000] {docker.py:438} INFO -   relation "channels" does not exist
[2024-07-26T00:02:25.340+0000] {docker.py:438} INFO -   LINE 13:         source_videos LEFT JOIN channels 
[2024-07-26T00:02:25.340+0000] {docker.py:438} INFO -                                            ^
[2024-07-26T00:02:25.340+0000] {docker.py:438} INFO -   compiled Code at target/run/youtube_elt_dbt/models/mart/trending_video_counts_per_channel.sql
[2024-07-26T00:02:25.341+0000] {docker.py:438} INFO - [0m00:02:25
[2024-07-26T00:02:25.341+0000] {docker.py:438} INFO - [0m00:02:25    Database Error in model view_ranks (models/mart/view_ranks.sql)
[2024-07-26T00:02:25.341+0000] {docker.py:438} INFO -   relation "channels" does not exist
[2024-07-26T00:02:25.341+0000] {docker.py:438} INFO -   LINE 15:                 channels
[2024-07-26T00:02:25.342+0000] {docker.py:438} INFO -                            ^
[2024-07-26T00:02:25.342+0000] {docker.py:438} INFO -   compiled Code at target/run/youtube_elt_dbt/models/mart/view_ranks.sql
[2024-07-26T00:02:25.342+0000] {docker.py:438} INFO - [0m00:02:25
[2024-07-26T00:02:25.343+0000] {docker.py:438} INFO - [0m00:02:25    Database Error in model word_counts_title_distinct (models/mart/word_counts_title_distinct.sql)
[2024-07-26T00:02:25.343+0000] {docker.py:438} INFO -   syntax error at or near "video_id"
[2024-07-26T00:02:25.343+0000] {docker.py:438} INFO -   LINE 12:         DISTINCT ON video_id
[2024-07-26T00:02:25.343+0000] {docker.py:438} INFO -                                ^
[2024-07-26T00:02:25.344+0000] {docker.py:438} INFO -   compiled Code at target/run/youtube_elt_dbt/models/mart/word_counts_title_distinct.sql
[2024-07-26T00:02:25.344+0000] {docker.py:438} INFO - [0m00:02:25
[2024-07-26T00:02:25.344+0000] {docker.py:438} INFO - [0m00:02:25  Done. PASS=4 WARN=0 ERROR=3 SKIP=0 TOTAL=7
[2024-07-26T00:02:26.322+0000] {taskinstance.py:441} INFO - ::group::Post task execution logs
[2024-07-26T00:02:26.330+0000] {taskinstance.py:2905} ERROR - Task failed with exception
Traceback (most recent call last):
  File "/home/airflow/.local/lib/python3.12/site-packages/docker/api/client.py", line 275, in _raise_for_status
    response.raise_for_status()
  File "/home/airflow/.local/lib/python3.12/site-packages/requests/models.py", line 1024, in raise_for_status
    raise HTTPError(http_error_msg, response=self)
requests.exceptions.HTTPError: 400 Client Error: Bad Request for url: http+docker://localhost/v1.45/containers/create

The above exception was the direct cause of the following exception:

Traceback (most recent call last):
  File "/home/airflow/.local/lib/python3.12/site-packages/airflow/providers/docker/operators/docker.py", line 372, in _run_image
    return self._run_image_with_mounts([*self.mounts, tmp_mount], add_tmp_variable=True)
           ^^^^^^^^^^^^^^^^^^^^^^^^^^^^^^^^^^^^^^^^^^^^^^^^^^^^^^^^^^^^^^^^^^^^^^^^^^^^^
  File "/home/airflow/.local/lib/python3.12/site-packages/airflow/providers/docker/operators/docker.py", line 399, in _run_image_with_mounts
    self.container = self.cli.create_container(
                     ^^^^^^^^^^^^^^^^^^^^^^^^^^
  File "/home/airflow/.local/lib/python3.12/site-packages/docker/api/container.py", line 440, in create_container
    return self.create_container_from_config(config, name, platform)
           ^^^^^^^^^^^^^^^^^^^^^^^^^^^^^^^^^^^^^^^^^^^^^^^^^^^^^^^^^
  File "/home/airflow/.local/lib/python3.12/site-packages/docker/api/container.py", line 457, in create_container_from_config
    return self._result(res, True)
           ^^^^^^^^^^^^^^^^^^^^^^^
  File "/home/airflow/.local/lib/python3.12/site-packages/docker/api/client.py", line 281, in _result
    self._raise_for_status(response)
  File "/home/airflow/.local/lib/python3.12/site-packages/docker/api/client.py", line 277, in _raise_for_status
    raise create_api_error_from_http_exception(e) from e
          ^^^^^^^^^^^^^^^^^^^^^^^^^^^^^^^^^^^^^^^
  File "/home/airflow/.local/lib/python3.12/site-packages/docker/errors.py", line 39, in create_api_error_from_http_exception
    raise cls(e, response=response, explanation=explanation) from e
docker.errors.APIError: 400 Client Error for http+docker://localhost/v1.45/containers/create: Bad Request ("invalid mount config for type "bind": bind source path does not exist: /tmp/airflowtmpfmjdcy_8")

During handling of the above exception, another exception occurred:

Traceback (most recent call last):
  File "/home/airflow/.local/lib/python3.12/site-packages/airflow/models/taskinstance.py", line 465, in _execute_task
    result = _execute_callable(context=context, **execute_callable_kwargs)
             ^^^^^^^^^^^^^^^^^^^^^^^^^^^^^^^^^^^^^^^^^^^^^^^^^^^^^^^^^^^^^
  File "/home/airflow/.local/lib/python3.12/site-packages/airflow/models/taskinstance.py", line 432, in _execute_callable
    return execute_callable(context=context, **execute_callable_kwargs)
           ^^^^^^^^^^^^^^^^^^^^^^^^^^^^^^^^^^^^^^^^^^^^^^^^^^^^^^^^^^^^
  File "/home/airflow/.local/lib/python3.12/site-packages/airflow/models/baseoperator.py", line 401, in wrapper
    return func(self, *args, **kwargs)
           ^^^^^^^^^^^^^^^^^^^^^^^^^^^
  File "/home/airflow/.local/lib/python3.12/site-packages/airflow/providers/docker/operators/docker.py", line 513, in execute
    return self._run_image()
           ^^^^^^^^^^^^^^^^^
  File "/home/airflow/.local/lib/python3.12/site-packages/airflow/providers/docker/operators/docker.py", line 381, in _run_image
    return self._run_image_with_mounts(self.mounts, add_tmp_variable=False)
           ^^^^^^^^^^^^^^^^^^^^^^^^^^^^^^^^^^^^^^^^^^^^^^^^^^^^^^^^^^^^^^^^
  File "/home/airflow/.local/lib/python3.12/site-packages/airflow/providers/docker/operators/docker.py", line 446, in _run_image_with_mounts
    raise DockerContainerFailedException(f"Docker container failed: {result!r}", logs=log_lines)
airflow.providers.docker.exceptions.DockerContainerFailedException: Docker container failed: {'StatusCode': 1}
[2024-07-26T00:02:26.335+0000] {taskinstance.py:1206} INFO - Marking task as FAILED. dag_id=elt_script_dag, task_id=run_dbt, run_id=scheduled__2024-07-25T00:00:00+00:00, execution_date=20240725T000000, start_date=20240726T000222, end_date=20240726T000226
[2024-07-26T00:02:26.347+0000] {standard_task_runner.py:110} ERROR - Failed to execute job 121 for task run_dbt (Docker container failed: {'StatusCode': 1}; 1504)
[2024-07-26T00:02:26.374+0000] {local_task_job_runner.py:243} INFO - Task exited with return code 1
[2024-07-26T00:02:26.387+0000] {taskinstance.py:3503} INFO - 0 downstream tasks scheduled from follow-on schedule check
[2024-07-26T00:02:26.389+0000] {local_task_job_runner.py:222} INFO - ::endgroup::
