[2024-07-26T00:01:17.132+0000] {local_task_job_runner.py:120} INFO - ::group::Pre task execution logs
[2024-07-26T00:01:17.148+0000] {taskinstance.py:2076} INFO - Dependencies all met for dep_context=non-requeueable deps ti=<TaskInstance: elt_script_dag.run_dbt scheduled__2024-07-25T00:00:00+00:00 [queued]>
[2024-07-26T00:01:17.154+0000] {taskinstance.py:2076} INFO - Dependencies all met for dep_context=requeueable deps ti=<TaskInstance: elt_script_dag.run_dbt scheduled__2024-07-25T00:00:00+00:00 [queued]>
[2024-07-26T00:01:17.154+0000] {taskinstance.py:2306} INFO - Starting attempt 1 of 2
[2024-07-26T00:01:17.164+0000] {taskinstance.py:2330} INFO - Executing <Task(DockerOperator): run_dbt> on 2024-07-25 00:00:00+00:00
[2024-07-26T00:01:17.170+0000] {warnings.py:112} WARNING - /home/***/.local/lib/python3.12/site-packages/***/task/task_runner/standard_task_runner.py:62: DeprecationWarning: This process (pid=1485) is multi-threaded, use of fork() may lead to deadlocks in the child.
  pid = os.fork()

[2024-07-26T00:01:17.171+0000] {standard_task_runner.py:64} INFO - Started process 1487 to run task
[2024-07-26T00:01:17.171+0000] {standard_task_runner.py:90} INFO - Running: ['***', 'tasks', 'run', 'elt_script_dag', 'run_dbt', 'scheduled__2024-07-25T00:00:00+00:00', '--job-id', '120', '--raw', '--subdir', 'DAGS_FOLDER/dag.py', '--cfg-path', '/tmp/tmpsts1wlci']
[2024-07-26T00:01:17.172+0000] {standard_task_runner.py:91} INFO - Job 120: Subtask run_dbt
[2024-07-26T00:01:17.204+0000] {task_command.py:426} INFO - Running <TaskInstance: elt_script_dag.run_dbt scheduled__2024-07-25T00:00:00+00:00 [running]> on host 6a3ef3606308
[2024-07-26T00:01:17.267+0000] {taskinstance.py:2648} INFO - Exporting env vars: AIRFLOW_CTX_DAG_EMAIL='***@example.com' AIRFLOW_CTX_DAG_OWNER='***' AIRFLOW_CTX_DAG_ID='elt_script_dag' AIRFLOW_CTX_TASK_ID='run_dbt' AIRFLOW_CTX_EXECUTION_DATE='2024-07-25T00:00:00+00:00' AIRFLOW_CTX_TRY_NUMBER='1' AIRFLOW_CTX_DAG_RUN_ID='scheduled__2024-07-25T00:00:00+00:00'
[2024-07-26T00:01:17.269+0000] {taskinstance.py:430} INFO - ::endgroup::
[2024-07-26T00:01:17.290+0000] {docker.py:367} INFO - Starting docker container from image ghcr.io/dbt-labs/dbt-postgres:1.8.2
[2024-07-26T00:01:17.297+0000] {docker.py:375} WARNING - Using remote engine or docker-in-docker and mounting temporary volume from host is not supported. Falling back to `mount_tmp_dir=False` mode. You can set `mount_tmp_dir` parameter to False to disable mounting and remove the warning
[2024-07-26T00:01:18.555+0000] {docker.py:438} INFO - [0m00:01:18  Running with dbt=1.8.3
[2024-07-26T00:01:18.693+0000] {docker.py:438} INFO - [0m00:01:18  Registered adapter: postgres=1.8.2
[2024-07-26T00:01:18.782+0000] {docker.py:438} INFO - [0m00:01:18  Unable to do partial parsing because config vars, config profile, or config target have changed
[2024-07-26T00:01:19.893+0000] {docker.py:438} INFO - [0m00:01:19  Found 7 models, 27 data tests, 415 macros
[2024-07-26T00:01:19.897+0000] {docker.py:438} INFO - [0m00:01:19
[2024-07-26T00:01:20.026+0000] {docker.py:438} INFO - [0m00:01:20  Concurrency: 1 threads (target='dev')
[2024-07-26T00:01:20.027+0000] {docker.py:438} INFO - [0m00:01:20
[2024-07-26T00:01:20.036+0000] {docker.py:438} INFO - [0m00:01:20  1 of 7 START sql view model public.channel_rankings ............................ [RUN]
[2024-07-26T00:01:20.154+0000] {docker.py:438} INFO - [0m00:01:20  1 of 7 OK created sql view model public.channel_rankings ....................... [[32mCREATE VIEW[0m in 0.12s]
[2024-07-26T00:01:20.157+0000] {docker.py:438} INFO - [0m00:01:20  2 of 7 START sql view model public.source_stop_words ........................... [RUN]
[2024-07-26T00:01:20.216+0000] {docker.py:438} INFO - [0m00:01:20  2 of 7 OK created sql view model public.source_stop_words ...................... [[32mCREATE VIEW[0m in 0.06s]
[2024-07-26T00:01:20.219+0000] {docker.py:438} INFO - [0m00:01:20  3 of 7 START sql view model public.source_videos ............................... [RUN]
[2024-07-26T00:01:20.286+0000] {docker.py:438} INFO - [0m00:01:20  3 of 7 OK created sql view model public.source_videos .......................... [[32mCREATE VIEW[0m in 0.06s]
[2024-07-26T00:01:20.288+0000] {docker.py:438} INFO - [0m00:01:20  4 of 7 START sql view model public.trending_video_counts_per_channel ........... [RUN]
[2024-07-26T00:01:20.349+0000] {docker.py:438} INFO - [0m00:01:20  4 of 7 OK created sql view model public.trending_video_counts_per_channel ...... [[32mCREATE VIEW[0m in 0.06s]
[2024-07-26T00:01:20.352+0000] {docker.py:438} INFO - [0m00:01:20  5 of 7 START sql view model public.view_ranks .................................. [RUN]
[2024-07-26T00:01:20.396+0000] {docker.py:438} INFO - [0m00:01:20  5 of 7 ERROR creating sql view model public.view_ranks ......................... [[31mERROR[0m in 0.04s]
[2024-07-26T00:01:20.399+0000] {docker.py:438} INFO - [0m00:01:20  6 of 7 START sql view model public.word_counts_title ........................... [RUN]
[2024-07-26T00:01:20.461+0000] {docker.py:438} INFO - [0m00:01:20  6 of 7 OK created sql view model public.word_counts_title ...................... [[32mCREATE VIEW[0m in 0.06s]
[2024-07-26T00:01:20.464+0000] {docker.py:438} INFO - [0m00:01:20  7 of 7 START sql view model public.word_counts_title_distinct .................. [RUN]
[2024-07-26T00:01:20.509+0000] {docker.py:438} INFO - [0m00:01:20  7 of 7 ERROR creating sql view model public.word_counts_title_distinct ......... [[31mERROR[0m in 0.04s]
[2024-07-26T00:01:20.531+0000] {docker.py:438} INFO - [0m00:01:20
[2024-07-26T00:01:20.531+0000] {docker.py:438} INFO - [0m00:01:20  Finished running 7 view models in 0 hours 0 minutes and 0.63 seconds (0.63s).
[2024-07-26T00:01:20.575+0000] {docker.py:438} INFO - [0m00:01:20
[2024-07-26T00:01:20.576+0000] {docker.py:438} INFO - [0m00:01:20  [31mCompleted with 2 errors and 0 warnings:[0m
[2024-07-26T00:01:20.577+0000] {docker.py:438} INFO - [0m00:01:20
[2024-07-26T00:01:20.577+0000] {docker.py:438} INFO - [0m00:01:20    Database Error in model view_ranks (models/mart/view_ranks.sql)
[2024-07-26T00:01:20.578+0000] {docker.py:438} INFO -   column "video_count" does not exist
[2024-07-26T00:01:20.578+0000] {docker.py:438} INFO -   LINE 11: ...   channel_name, views, channel_start_date, subs, video_coun...
[2024-07-26T00:01:20.578+0000] {docker.py:438} INFO -                                                                 ^
[2024-07-26T00:01:20.579+0000] {docker.py:438} INFO -   compiled Code at target/run/youtube_elt_dbt/models/mart/view_ranks.sql
[2024-07-26T00:01:20.579+0000] {docker.py:438} INFO - [0m00:01:20
[2024-07-26T00:01:20.579+0000] {docker.py:438} INFO - [0m00:01:20    Database Error in model word_counts_title_distinct (models/mart/word_counts_title_distinct.sql)
[2024-07-26T00:01:20.580+0000] {docker.py:438} INFO -   syntax error at or near "video_id"
[2024-07-26T00:01:20.580+0000] {docker.py:438} INFO -   LINE 12:         DISTINCT ON video_id
[2024-07-26T00:01:20.580+0000] {docker.py:438} INFO -                                ^
[2024-07-26T00:01:20.580+0000] {docker.py:438} INFO -   compiled Code at target/run/youtube_elt_dbt/models/mart/word_counts_title_distinct.sql
[2024-07-26T00:01:20.581+0000] {docker.py:438} INFO - [0m00:01:20
[2024-07-26T00:01:20.581+0000] {docker.py:438} INFO - [0m00:01:20  Done. PASS=5 WARN=0 ERROR=2 SKIP=0 TOTAL=7
[2024-07-26T00:01:21.683+0000] {taskinstance.py:441} INFO - ::group::Post task execution logs
[2024-07-26T00:01:21.694+0000] {taskinstance.py:2905} ERROR - Task failed with exception
Traceback (most recent call last):
  File "/home/airflow/.local/lib/python3.12/site-packages/docker/api/client.py", line 275, in _raise_for_status
    response.raise_for_status()
  File "/home/airflow/.local/lib/python3.12/site-packages/requests/models.py", line 1024, in raise_for_status
    raise HTTPError(http_error_msg, response=self)
requests.exceptions.HTTPError: 400 Client Error: Bad Request for url: http+docker://localhost/v1.45/containers/create

The above exception was the direct cause of the following exception:

Traceback (most recent call last):
  File "/home/airflow/.local/lib/python3.12/site-packages/airflow/providers/docker/operators/docker.py", line 372, in _run_image
    return self._run_image_with_mounts([*self.mounts, tmp_mount], add_tmp_variable=True)
           ^^^^^^^^^^^^^^^^^^^^^^^^^^^^^^^^^^^^^^^^^^^^^^^^^^^^^^^^^^^^^^^^^^^^^^^^^^^^^
  File "/home/airflow/.local/lib/python3.12/site-packages/airflow/providers/docker/operators/docker.py", line 399, in _run_image_with_mounts
    self.container = self.cli.create_container(
                     ^^^^^^^^^^^^^^^^^^^^^^^^^^
  File "/home/airflow/.local/lib/python3.12/site-packages/docker/api/container.py", line 440, in create_container
    return self.create_container_from_config(config, name, platform)
           ^^^^^^^^^^^^^^^^^^^^^^^^^^^^^^^^^^^^^^^^^^^^^^^^^^^^^^^^^
  File "/home/airflow/.local/lib/python3.12/site-packages/docker/api/container.py", line 457, in create_container_from_config
    return self._result(res, True)
           ^^^^^^^^^^^^^^^^^^^^^^^
  File "/home/airflow/.local/lib/python3.12/site-packages/docker/api/client.py", line 281, in _result
    self._raise_for_status(response)
  File "/home/airflow/.local/lib/python3.12/site-packages/docker/api/client.py", line 277, in _raise_for_status
    raise create_api_error_from_http_exception(e) from e
          ^^^^^^^^^^^^^^^^^^^^^^^^^^^^^^^^^^^^^^^
  File "/home/airflow/.local/lib/python3.12/site-packages/docker/errors.py", line 39, in create_api_error_from_http_exception
    raise cls(e, response=response, explanation=explanation) from e
docker.errors.APIError: 400 Client Error for http+docker://localhost/v1.45/containers/create: Bad Request ("invalid mount config for type "bind": bind source path does not exist: /tmp/airflowtmp5qxnm1lr")

During handling of the above exception, another exception occurred:

Traceback (most recent call last):
  File "/home/airflow/.local/lib/python3.12/site-packages/airflow/models/taskinstance.py", line 465, in _execute_task
    result = _execute_callable(context=context, **execute_callable_kwargs)
             ^^^^^^^^^^^^^^^^^^^^^^^^^^^^^^^^^^^^^^^^^^^^^^^^^^^^^^^^^^^^^
  File "/home/airflow/.local/lib/python3.12/site-packages/airflow/models/taskinstance.py", line 432, in _execute_callable
    return execute_callable(context=context, **execute_callable_kwargs)
           ^^^^^^^^^^^^^^^^^^^^^^^^^^^^^^^^^^^^^^^^^^^^^^^^^^^^^^^^^^^^
  File "/home/airflow/.local/lib/python3.12/site-packages/airflow/models/baseoperator.py", line 401, in wrapper
    return func(self, *args, **kwargs)
           ^^^^^^^^^^^^^^^^^^^^^^^^^^^
  File "/home/airflow/.local/lib/python3.12/site-packages/airflow/providers/docker/operators/docker.py", line 513, in execute
    return self._run_image()
           ^^^^^^^^^^^^^^^^^
  File "/home/airflow/.local/lib/python3.12/site-packages/airflow/providers/docker/operators/docker.py", line 381, in _run_image
    return self._run_image_with_mounts(self.mounts, add_tmp_variable=False)
           ^^^^^^^^^^^^^^^^^^^^^^^^^^^^^^^^^^^^^^^^^^^^^^^^^^^^^^^^^^^^^^^^
  File "/home/airflow/.local/lib/python3.12/site-packages/airflow/providers/docker/operators/docker.py", line 446, in _run_image_with_mounts
    raise DockerContainerFailedException(f"Docker container failed: {result!r}", logs=log_lines)
airflow.providers.docker.exceptions.DockerContainerFailedException: Docker container failed: {'StatusCode': 1}
[2024-07-26T00:01:21.702+0000] {taskinstance.py:1206} INFO - Marking task as UP_FOR_RETRY. dag_id=elt_script_dag, task_id=run_dbt, run_id=scheduled__2024-07-25T00:00:00+00:00, execution_date=20240725T000000, start_date=20240726T000117, end_date=20240726T000121
[2024-07-26T00:01:21.716+0000] {warnings.py:112} WARNING - /home/***/.local/lib/python3.12/site-packages/***/utils/email.py:154: RemovedInAirflow3Warning: Fetching SMTP credentials from configuration variables will be deprecated in a future release. Please set credentials using a connection instead.
  send_mime_email(e_from=mail_from, e_to=recipients, mime_msg=msg, conn_id=conn_id, dryrun=dryrun)

[2024-07-26T00:01:21.717+0000] {configuration.py:1053} WARNING - section/key [smtp/smtp_user] not found in config
[2024-07-26T00:01:21.717+0000] {email.py:271} INFO - Email alerting: attempt 1
[2024-07-26T00:01:21.723+0000] {configuration.py:1053} WARNING - section/key [smtp/smtp_user] not found in config
[2024-07-26T00:01:21.724+0000] {email.py:271} INFO - Email alerting: attempt 1
[2024-07-26T00:01:21.725+0000] {taskinstance.py:879} ERROR - Failed to send email to: ['***@example.com']
Traceback (most recent call last):
  File "/home/airflow/.local/lib/python3.12/site-packages/docker/api/client.py", line 275, in _raise_for_status
    response.raise_for_status()
  File "/home/airflow/.local/lib/python3.12/site-packages/requests/models.py", line 1024, in raise_for_status
    raise HTTPError(http_error_msg, response=self)
requests.exceptions.HTTPError: 400 Client Error: Bad Request for url: http+docker://localhost/v1.45/containers/create

The above exception was the direct cause of the following exception:

Traceback (most recent call last):
  File "/home/airflow/.local/lib/python3.12/site-packages/airflow/providers/docker/operators/docker.py", line 372, in _run_image
    return self._run_image_with_mounts([*self.mounts, tmp_mount], add_tmp_variable=True)
           ^^^^^^^^^^^^^^^^^^^^^^^^^^^^^^^^^^^^^^^^^^^^^^^^^^^^^^^^^^^^^^^^^^^^^^^^^^^^^
  File "/home/airflow/.local/lib/python3.12/site-packages/airflow/providers/docker/operators/docker.py", line 399, in _run_image_with_mounts
    self.container = self.cli.create_container(
                     ^^^^^^^^^^^^^^^^^^^^^^^^^^
  File "/home/airflow/.local/lib/python3.12/site-packages/docker/api/container.py", line 440, in create_container
    return self.create_container_from_config(config, name, platform)
           ^^^^^^^^^^^^^^^^^^^^^^^^^^^^^^^^^^^^^^^^^^^^^^^^^^^^^^^^^
  File "/home/airflow/.local/lib/python3.12/site-packages/docker/api/container.py", line 457, in create_container_from_config
    return self._result(res, True)
           ^^^^^^^^^^^^^^^^^^^^^^^
  File "/home/airflow/.local/lib/python3.12/site-packages/docker/api/client.py", line 281, in _result
    self._raise_for_status(response)
  File "/home/airflow/.local/lib/python3.12/site-packages/docker/api/client.py", line 277, in _raise_for_status
    raise create_api_error_from_http_exception(e) from e
          ^^^^^^^^^^^^^^^^^^^^^^^^^^^^^^^^^^^^^^^
  File "/home/airflow/.local/lib/python3.12/site-packages/docker/errors.py", line 39, in create_api_error_from_http_exception
    raise cls(e, response=response, explanation=explanation) from e
docker.errors.APIError: 400 Client Error for http+docker://localhost/v1.45/containers/create: Bad Request ("invalid mount config for type "bind": bind source path does not exist: /tmp/airflowtmp5qxnm1lr")

During handling of the above exception, another exception occurred:

Traceback (most recent call last):
  File "/home/airflow/.local/lib/python3.12/site-packages/airflow/models/taskinstance.py", line 2479, in _run_raw_task
    self._execute_task_with_callbacks(context, test_mode, session=session)
  File "/home/airflow/.local/lib/python3.12/site-packages/airflow/models/taskinstance.py", line 2676, in _execute_task_with_callbacks
    result = self._execute_task(context, task_orig)
             ^^^^^^^^^^^^^^^^^^^^^^^^^^^^^^^^^^^^^^
  File "/home/airflow/.local/lib/python3.12/site-packages/airflow/models/taskinstance.py", line 2701, in _execute_task
    return _execute_task(self, context, task_orig)
           ^^^^^^^^^^^^^^^^^^^^^^^^^^^^^^^^^^^^^^^
  File "/home/airflow/.local/lib/python3.12/site-packages/airflow/models/taskinstance.py", line 465, in _execute_task
    result = _execute_callable(context=context, **execute_callable_kwargs)
             ^^^^^^^^^^^^^^^^^^^^^^^^^^^^^^^^^^^^^^^^^^^^^^^^^^^^^^^^^^^^^
  File "/home/airflow/.local/lib/python3.12/site-packages/airflow/models/taskinstance.py", line 432, in _execute_callable
    return execute_callable(context=context, **execute_callable_kwargs)
           ^^^^^^^^^^^^^^^^^^^^^^^^^^^^^^^^^^^^^^^^^^^^^^^^^^^^^^^^^^^^
  File "/home/airflow/.local/lib/python3.12/site-packages/airflow/models/baseoperator.py", line 401, in wrapper
    return func(self, *args, **kwargs)
           ^^^^^^^^^^^^^^^^^^^^^^^^^^^
  File "/home/airflow/.local/lib/python3.12/site-packages/airflow/providers/docker/operators/docker.py", line 513, in execute
    return self._run_image()
           ^^^^^^^^^^^^^^^^^
  File "/home/airflow/.local/lib/python3.12/site-packages/airflow/providers/docker/operators/docker.py", line 381, in _run_image
    return self._run_image_with_mounts(self.mounts, add_tmp_variable=False)
           ^^^^^^^^^^^^^^^^^^^^^^^^^^^^^^^^^^^^^^^^^^^^^^^^^^^^^^^^^^^^^^^^
  File "/home/airflow/.local/lib/python3.12/site-packages/airflow/providers/docker/operators/docker.py", line 446, in _run_image_with_mounts
    raise DockerContainerFailedException(f"Docker container failed: {result!r}", logs=log_lines)
airflow.providers.docker.exceptions.DockerContainerFailedException: Docker container failed: {'StatusCode': 1}

During handling of the above exception, another exception occurred:

Traceback (most recent call last):
  File "/home/airflow/.local/lib/python3.12/site-packages/airflow/models/taskinstance.py", line 1063, in _email_alert
    send_email(task.email, subject, html_content)
  File "/home/airflow/.local/lib/python3.12/site-packages/airflow/utils/email.py", line 80, in send_email
    return backend(
           ^^^^^^^^
  File "/home/airflow/.local/lib/python3.12/site-packages/airflow/utils/email.py", line 154, in send_email_smtp
    send_mime_email(e_from=mail_from, e_to=recipients, mime_msg=msg, conn_id=conn_id, dryrun=dryrun)
  File "/home/airflow/.local/lib/python3.12/site-packages/airflow/utils/email.py", line 273, in send_mime_email
    smtp_conn = _get_smtp_connection(smtp_host, smtp_port, smtp_timeout, smtp_ssl)
                ^^^^^^^^^^^^^^^^^^^^^^^^^^^^^^^^^^^^^^^^^^^^^^^^^^^^^^^^^^^^^^^^^^
  File "/home/airflow/.local/lib/python3.12/site-packages/airflow/utils/email.py", line 317, in _get_smtp_connection
    return smtplib.SMTP(host=host, port=port, timeout=timeout)
           ^^^^^^^^^^^^^^^^^^^^^^^^^^^^^^^^^^^^^^^^^^^^^^^^^^^
  File "/usr/local/lib/python3.12/smtplib.py", line 255, in __init__
    (code, msg) = self.connect(host, port)
                  ^^^^^^^^^^^^^^^^^^^^^^^^
  File "/usr/local/lib/python3.12/smtplib.py", line 341, in connect
    self.sock = self._get_socket(host, port, self.timeout)
                ^^^^^^^^^^^^^^^^^^^^^^^^^^^^^^^^^^^^^^^^^^
  File "/usr/local/lib/python3.12/smtplib.py", line 312, in _get_socket
    return socket.create_connection((host, port), timeout,
           ^^^^^^^^^^^^^^^^^^^^^^^^^^^^^^^^^^^^^^^^^^^^^^^
  File "/usr/local/lib/python3.12/socket.py", line 853, in create_connection
    raise exceptions[0]
  File "/usr/local/lib/python3.12/socket.py", line 838, in create_connection
    sock.connect(sa)
ConnectionRefusedError: [Errno 111] Connection refused

During handling of the above exception, another exception occurred:

Traceback (most recent call last):
  File "/home/airflow/.local/lib/python3.12/site-packages/airflow/models/taskinstance.py", line 877, in _handle_failure
    task_instance.email_alert(error, failure_context["task"])
  File "/home/airflow/.local/lib/python3.12/site-packages/airflow/models/taskinstance.py", line 3163, in email_alert
    _email_alert(task_instance=self, exception=exception, task=task)
  File "/home/airflow/.local/lib/python3.12/site-packages/airflow/models/taskinstance.py", line 1065, in _email_alert
    send_email(task.email, subject, html_content_err)
  File "/home/airflow/.local/lib/python3.12/site-packages/airflow/utils/email.py", line 80, in send_email
    return backend(
           ^^^^^^^^
  File "/home/airflow/.local/lib/python3.12/site-packages/airflow/utils/email.py", line 154, in send_email_smtp
    send_mime_email(e_from=mail_from, e_to=recipients, mime_msg=msg, conn_id=conn_id, dryrun=dryrun)
  File "/home/airflow/.local/lib/python3.12/site-packages/airflow/utils/email.py", line 273, in send_mime_email
    smtp_conn = _get_smtp_connection(smtp_host, smtp_port, smtp_timeout, smtp_ssl)
                ^^^^^^^^^^^^^^^^^^^^^^^^^^^^^^^^^^^^^^^^^^^^^^^^^^^^^^^^^^^^^^^^^^
  File "/home/airflow/.local/lib/python3.12/site-packages/airflow/utils/email.py", line 317, in _get_smtp_connection
    return smtplib.SMTP(host=host, port=port, timeout=timeout)
           ^^^^^^^^^^^^^^^^^^^^^^^^^^^^^^^^^^^^^^^^^^^^^^^^^^^
  File "/usr/local/lib/python3.12/smtplib.py", line 255, in __init__
    (code, msg) = self.connect(host, port)
                  ^^^^^^^^^^^^^^^^^^^^^^^^
  File "/usr/local/lib/python3.12/smtplib.py", line 341, in connect
    self.sock = self._get_socket(host, port, self.timeout)
                ^^^^^^^^^^^^^^^^^^^^^^^^^^^^^^^^^^^^^^^^^^
  File "/usr/local/lib/python3.12/smtplib.py", line 312, in _get_socket
    return socket.create_connection((host, port), timeout,
           ^^^^^^^^^^^^^^^^^^^^^^^^^^^^^^^^^^^^^^^^^^^^^^^
  File "/usr/local/lib/python3.12/socket.py", line 853, in create_connection
    raise exceptions[0]
  File "/usr/local/lib/python3.12/socket.py", line 838, in create_connection
    sock.connect(sa)
ConnectionRefusedError: [Errno 111] Connection refused
[2024-07-26T00:01:21.738+0000] {standard_task_runner.py:110} ERROR - Failed to execute job 120 for task run_dbt (Docker container failed: {'StatusCode': 1}; 1487)
[2024-07-26T00:01:21.765+0000] {local_task_job_runner.py:243} INFO - Task exited with return code 1
[2024-07-26T00:01:21.781+0000] {taskinstance.py:3503} INFO - 0 downstream tasks scheduled from follow-on schedule check
[2024-07-26T00:01:21.783+0000] {local_task_job_runner.py:222} INFO - ::endgroup::
