[2024-07-23T04:13:56.435+0000] {local_task_job_runner.py:120} INFO - ::group::Pre task execution logs
[2024-07-23T04:13:56.456+0000] {taskinstance.py:2076} INFO - Dependencies all met for dep_context=non-requeueable deps ti=<TaskInstance: elt_script_dag.run_elt_script manual__2024-07-23T04:12:51.644757+00:00 [queued]>
[2024-07-23T04:13:56.463+0000] {taskinstance.py:2076} INFO - Dependencies all met for dep_context=requeueable deps ti=<TaskInstance: elt_script_dag.run_elt_script manual__2024-07-23T04:12:51.644757+00:00 [queued]>
[2024-07-23T04:13:56.464+0000] {taskinstance.py:2306} INFO - Starting attempt 2 of 2
[2024-07-23T04:13:56.474+0000] {taskinstance.py:2330} INFO - Executing <Task(BashOperator): run_elt_script> on 2024-07-23 04:12:51.644757+00:00
[2024-07-23T04:13:56.481+0000] {warnings.py:112} WARNING - /home/***/.local/lib/python3.12/site-packages/***/task/task_runner/standard_task_runner.py:62: DeprecationWarning: This process (pid=98) is multi-threaded, use of fork() may lead to deadlocks in the child.
  pid = os.fork()

[2024-07-23T04:13:56.482+0000] {standard_task_runner.py:64} INFO - Started process 100 to run task
[2024-07-23T04:13:56.482+0000] {standard_task_runner.py:90} INFO - Running: ['***', 'tasks', 'run', 'elt_script_dag', 'run_elt_script', 'manual__2024-07-23T04:12:51.644757+00:00', '--job-id', '19', '--raw', '--subdir', 'DAGS_FOLDER/dag.py', '--cfg-path', '/tmp/tmprim_1ndb']
[2024-07-23T04:13:56.483+0000] {standard_task_runner.py:91} INFO - Job 19: Subtask run_elt_script
[2024-07-23T04:13:56.518+0000] {task_command.py:426} INFO - Running <TaskInstance: elt_script_dag.run_elt_script manual__2024-07-23T04:12:51.644757+00:00 [running]> on host f010ea18e9b8
[2024-07-23T04:13:56.579+0000] {taskinstance.py:2648} INFO - Exporting env vars: AIRFLOW_CTX_DAG_EMAIL='***@example.com' AIRFLOW_CTX_DAG_OWNER='***' AIRFLOW_CTX_DAG_ID='elt_script_dag' AIRFLOW_CTX_TASK_ID='run_elt_script' AIRFLOW_CTX_EXECUTION_DATE='2024-07-23T04:12:51.644757+00:00' AIRFLOW_CTX_TRY_NUMBER='2' AIRFLOW_CTX_DAG_RUN_ID='manual__2024-07-23T04:12:51.644757+00:00'
[2024-07-23T04:13:56.580+0000] {taskinstance.py:430} INFO - ::endgroup::
[2024-07-23T04:13:56.581+0000] {subprocess.py:63} INFO - Tmp dir root location: /tmp
[2024-07-23T04:13:56.582+0000] {subprocess.py:75} INFO - Running command: ['/usr/bin/bash', '-c', 'python /elt_script.py']
[2024-07-23T04:13:56.594+0000] {subprocess.py:86} INFO - Output:
[2024-07-23T04:13:56.643+0000] {subprocess.py:93} INFO - python: can't open file '/elt_script.py': [Errno 2] No such file or directory
[2024-07-23T04:13:56.646+0000] {subprocess.py:97} INFO - Command exited with return code 2
[2024-07-23T04:13:56.647+0000] {taskinstance.py:441} INFO - ::group::Post task execution logs
[2024-07-23T04:13:56.655+0000] {taskinstance.py:2905} ERROR - Task failed with exception
Traceback (most recent call last):
  File "/home/airflow/.local/lib/python3.12/site-packages/airflow/models/taskinstance.py", line 465, in _execute_task
    result = _execute_callable(context=context, **execute_callable_kwargs)
             ^^^^^^^^^^^^^^^^^^^^^^^^^^^^^^^^^^^^^^^^^^^^^^^^^^^^^^^^^^^^^
  File "/home/airflow/.local/lib/python3.12/site-packages/airflow/models/taskinstance.py", line 432, in _execute_callable
    return execute_callable(context=context, **execute_callable_kwargs)
           ^^^^^^^^^^^^^^^^^^^^^^^^^^^^^^^^^^^^^^^^^^^^^^^^^^^^^^^^^^^^
  File "/home/airflow/.local/lib/python3.12/site-packages/airflow/models/baseoperator.py", line 401, in wrapper
    return func(self, *args, **kwargs)
           ^^^^^^^^^^^^^^^^^^^^^^^^^^^
  File "/home/airflow/.local/lib/python3.12/site-packages/airflow/operators/bash.py", line 243, in execute
    raise AirflowException(
airflow.exceptions.AirflowException: Bash command failed. The command returned a non-zero exit code 2.
[2024-07-23T04:13:56.659+0000] {taskinstance.py:1206} INFO - Marking task as FAILED. dag_id=elt_script_dag, task_id=run_elt_script, run_id=manual__2024-07-23T04:12:51.644757+00:00, execution_date=20240723T041251, start_date=20240723T041356, end_date=20240723T041356
[2024-07-23T04:13:56.670+0000] {standard_task_runner.py:110} ERROR - Failed to execute job 19 for task run_elt_script (Bash command failed. The command returned a non-zero exit code 2.; 100)
[2024-07-23T04:13:56.696+0000] {local_task_job_runner.py:243} INFO - Task exited with return code 1
[2024-07-23T04:13:56.710+0000] {taskinstance.py:3503} INFO - 0 downstream tasks scheduled from follow-on schedule check
[2024-07-23T04:13:56.711+0000] {local_task_job_runner.py:222} INFO - ::endgroup::
